<mujoco model="inspire_hand_right">
  <compiler angle="radian" autolimits="true" />
  <option gravity="0 0 0" timestep="0.001" />
  <visual>
    <global offwidth="3840" offheight="2160" />
  </visual>
  <asset>
    <mesh name="right_thumb_proximal_base_collision000" content_type="model/obj" file="meshes/collision/right_thumb_proximal_base_collision000.obj" />
    <mesh name="right_thumb_proximal_base_collision001" content_type="model/obj" file="meshes/collision/right_thumb_proximal_base_collision001.obj" />
    <mesh name="right_thumb_proximal_collision000" content_type="model/obj" file="meshes/collision/right_thumb_proximal_collision000.obj" />
    <mesh name="right_thumb_intermediate_collision000" content_type="model/obj" file="meshes/collision/right_thumb_intermediate_collision000.obj" />
    <mesh name="right_thumb_distal_collision000" content_type="model/obj" file="meshes/collision/right_thumb_distal_collision000.obj" />
    <mesh name="right_thumb_distal_collision001" content_type="model/obj" file="meshes/collision/right_thumb_distal_collision001.obj" />
    <mesh name="right_index_proximal_collision000" content_type="model/obj" file="meshes/collision/right_index_proximal_collision000.obj" />
    <mesh name="right_index_proximal_collision001" content_type="model/obj" file="meshes/collision/right_index_proximal_collision001.obj" />
    <mesh name="right_index_intermediate_collision000" content_type="model/obj" file="meshes/collision/right_index_intermediate_collision000.obj" />
    <mesh name="right_index_intermediate_collision001" content_type="model/obj" file="meshes/collision/right_index_intermediate_collision001.obj" />
    <mesh name="right_index_intermediate_collision002" content_type="model/obj" file="meshes/collision/right_index_intermediate_collision002.obj" />
    <mesh name="right_middle_intermediate_collision000" content_type="model/obj" file="meshes/collision/right_middle_intermediate_collision000.obj" />
    <mesh name="right_pinky_intermediate_collision000" content_type="model/obj" file="meshes/collision/right_pinky_intermediate_collision000.obj" />
    <texture type="skybox" builtin="gradient" rgb1="1 1 1" rgb2="1 1 1" width="32" height="512" />
  </asset>
  <worldbody>
    <light pos="0 0 5" dir="0 0 -1" directional="true" />
    <body name="hand_root">
      <body name="hand_base_link" quat="9.38189e-07 -9.38183e-07 -0.707105 0.707109">
        <inertial pos="-0.0025264 -0.066047 0.0019598" quat="0.993005 -0.113528 -0.0210604 0.0246792" mass="0.14143" diaginertia="0.000122991 8.41186e-05 7.61951e-05" />
        <geom size="0.028 0.0139" pos="0 -0.0136 0" quat="0.707109 0.707105 0 0" type="cylinder" group="1" rgba="0.9 0.35 0.1 0.65" />
        <geom size="0.01955 0.0101 0.0287" pos="-0.0032 -0.038 0" type="box" group="1" rgba="0.9 0.35 0.1 0.65" />
        <geom size="0.01955 0.02 0.0407" pos="-0.0032 -0.0682 0" type="box" group="1" rgba="0.9 0.35 0.1 0.65" />
        <geom size="0.0161 0.02 0.0407" pos="0 -0.1081 0" type="box" group="1" rgba="0.9 0.35 0.1 0.65" />
        <geom size="0.00625 0.00555 0.00445" pos="-0.0016 -0.134 0.0309" type="box" group="1" rgba="0.9 0.35 0.1 0.65" />
        <geom size="0.00625 0.00555 0.00445" pos="-0.0016 -0.134 0.0118" type="box" group="1" rgba="0.9 0.35 0.1 0.65" />
        <geom size="0.00625 0.00555 0.00445" pos="-0.0016 -0.134 -0.007" type="box" group="1" rgba="0.9 0.35 0.1 0.65" />
        <geom size="0.00625 0.00555 0.00445" pos="-0.0016 -0.134 -0.0262" type="box" group="1" rgba="0.9 0.35 0.1 0.65" />
        <body name="thumb_proximal_base" pos="-0.01696 -0.0691 -0.02045" quat="0.499998 0.5 -0.5 0.500002">
          <inertial pos="-0.0048064 0.0009382 -0.00757" quat="0.515015 0.680854 0.408023 0.323596" mass="0.0018869" diaginertia="8.66026e-08 6.8732e-08 4.94194e-08" />
          <joint name="thumb_proximal_yaw_joint" pos="0 0 0" axis="0 0 -1" range="0 1.308" actuatorfrcrange="-1 1" damping="0.1" armature="0.0002" frictionloss="0.0" />
          <geom name="thumb_proximal_base_collision_part000" type="mesh" mesh="right_thumb_proximal_base_collision000" group="1" rgba="0.9 0.35 0.1 0.65" />
          <geom name="thumb_proximal_base_collision_part001" type="mesh" mesh="right_thumb_proximal_base_collision001" group="1" rgba="0.9 0.35 0.1 0.65" />
          <body name="thumb_proximal" pos="-0.0088099 0.010892 -0.00925" quat="0.0996843 0.0996847 0.700046 0.700044">
            <inertial pos="0.021932 0.012785 -0.0080386" quat="-0.254474 0.660716 0.251893 0.659733" mass="0.0066075" diaginertia="2.78601e-06 2.43933e-06 8.64566e-07" />
            <joint name="thumb_proximal_pitch_joint" pos="0 0 0" axis="0 0 1" range="0 0.6" actuatorfrcrange="-1 1" damping="0.1" armature="0.0002" frictionloss="0.0" />
            <geom type="mesh" mesh="right_thumb_proximal_collision000" group="1" rgba="0.9 0.35 0.1 0.65" />
            <body name="thumb_intermediate" pos="0.04407 0.034553 -0.0008">
              <inertial pos="0.0095544 -0.0016282 -0.0071997" quat="0.636718 0.307389 -0.636802 0.307548" mass="0.0037847" diaginertia="4.6531e-07 4.48089e-07 2.45661e-07" />
              <joint name="thumb_intermediate_joint" pos="0 0 0" axis="0 0 1" range="0 0.8" actuatorfrcrange="-1 1" damping="0.0" armature="0.0" frictionloss="0.0" />
              <geom type="mesh" mesh="right_thumb_intermediate_collision000" group="1" rgba="0.9 0.35 0.1 0.65" />
              <body name="thumb_distal" pos="0.020248 0.010156 -0.0012">
                <inertial pos="0.0092888 0.0049529 -0.0060033" quat="-0.266294 0.655967 0.262806 0.655537" mass="0.0033441" diaginertia="2.0026e-07 1.95247e-07 8.1593e-08" />
                <joint name="thumb_distal_joint" pos="0 0 0" axis="0 0 1" range="0 0.4" actuatorfrcrange="-1 1" damping="0.0" armature="0.0" frictionloss="0.0" />
                <geom name="thumb_distal_collision_part000" type="mesh" mesh="right_thumb_distal_collision000" group="1" rgba="0.9 0.35 0.1 0.65" />
                <geom name="thumb_distal_collision_part001" type="mesh" mesh="right_thumb_distal_collision001" group="1" rgba="0.9 0.35 0.1 0.65" />
                <body name="thumb_tip" pos="0.0202 0.014 -0.006" />
              </body>
            </body>
          </body>
        </body>
        <body name="index_proximal" pos="0.00028533 -0.13653 -0.032268" quat="0.0174454 -0.999848 0 0">
          <inertial pos="0.0012259 0.011942 -0.0060001" quat="0.50867 0.49121 -0.508643 0.491172" mass="0.0042403" diaginertia="6.9398e-07 6.62871e-07 2.10909e-07" />
          <joint name="index_proximal_joint" pos="0 0 0" axis="0 0 1" range="0 1.47" actuatorfrcrange="-1 1" damping="0.1" armature="0.0002" frictionloss="0.0" />
          <geom name="index_proximal_collision_part000" type="mesh" mesh="right_index_proximal_collision000" group="1" rgba="0.9 0.35 0.1 0.65" />
          <geom name="index_proximal_collision_part001" type="mesh" mesh="right_index_proximal_collision001" group="1" rgba="0.9 0.35 0.1 0.65" />
          <body name="index_intermediate" pos="-0.0026138 0.032026 -0.001">
            <inertial pos="0.0019697 0.019589 -0.005" quat="0.466773 0.531152 -0.466773 0.531153" mass="0.0045683" diaginertia="7.8179e-07 7.72465e-07 8.47212e-08" />
            <joint name="index_intermediate_joint" pos="0 0 0" axis="0 0 1" range="-0.04545 1.56" actuatorfrcrange="-1 1" damping="0.0" armature="0.0" frictionloss="0.0" />
            <geom name="index_intermediate_collision_part000" type="mesh" mesh="right_index_intermediate_collision000" group="1" rgba="0.9 0.35 0.1 0.65" />
            <geom name="index_intermediate_collision_part001" type="mesh" mesh="right_index_intermediate_collision001" group="1" rgba="0.9 0.35 0.1 0.65" />
            <geom name="index_intermediate_collision_part002" type="mesh" mesh="right_index_intermediate_collision002" group="1" rgba="0.9 0.35 0.1 0.65" />
            <body name="index_tip" pos="-0.0008 0.045 -0.005" />
          </body>
        </body>
        <body name="middle_proximal" pos="0.00028533 -0.1371 -0.01295" quat="-3.67321e-06 -1 0 0">
          <inertial pos="0.001297 0.011934 -0.0060001" quat="0.510131 0.489693 -0.510105 0.489653" mass="0.0042403" diaginertia="6.9397e-07 6.62865e-07 2.10915e-07" />
          <joint name="middle_proximal_joint" pos="0 0 0" axis="0 0 1" range="0 1.47" actuatorfrcrange="-1 1" damping="0.1" armature="0.0002" frictionloss="0.0" />
          <geom name="middle_proximal_collision_part000" type="mesh" mesh="right_index_proximal_collision000" group="1" rgba="0.9 0.35 0.1 0.65" />
          <geom name="middle_proximal_collision_part001" type="mesh" mesh="right_index_proximal_collision001" group="1" rgba="0.9 0.35 0.1 0.65" />
          <body name="middle_intermediate" pos="-0.0024229 0.032041 -0.001">
            <inertial pos="0.001921 0.020796 -0.005" quat="0.466148 0.531627 -0.466229 0.531705" mass="0.0050396" diaginertia="9.8384e-07 9.73279e-07 9.14014e-08" />
            <joint name="middle_intermediate_joint" pos="0 0 0" axis="0 0 1" range="-0.04545 1.56" actuatorfrcrange="-1 1" damping="0.0" armature="0.0" frictionloss="0.0" />
            <geom type="mesh" mesh="right_middle_intermediate_collision000" group="1" rgba="0.9 0.35 0.1 0.65" />
            <body name="middle_tip" pos="-0.001 0.048 -0.005" />
          </body>
        </body>
        <body name="ring_proximal" pos="0.00028533 -0.13691 0.0062872" quat="0.0261933 0.999657 0 0">
          <inertial pos="0.001297 0.011934 -0.0060002" quat="0.510129 0.489691 -0.510107 0.489654" mass="0.0042403" diaginertia="6.9397e-07 6.62865e-07 2.10915e-07" />
          <joint name="ring_proximal_joint" pos="0 0 0" axis="0 0 1" range="0 1.47" actuatorfrcrange="-1 1" damping="0.1" armature="0.0002" frictionloss="0.0" />
          <geom name="ring_proximal_collision_part000" type="mesh" mesh="right_index_proximal_collision000" group="1" rgba="0.9 0.35 0.1 0.65" />
          <geom name="ring_proximal_collision_part001" type="mesh" mesh="right_index_proximal_collision001" group="1" rgba="0.9 0.35 0.1 0.65" />
          <body name="ring_intermediate" pos="-0.0024229 0.032041 -0.001">
            <inertial pos="0.0021753 0.019567 -0.005" quat="0.469554 0.528695 -0.469554 0.528695" mass="0.0045683" diaginertia="7.8177e-07 7.72448e-07 8.4722e-08" />
            <joint name="ring_intermediate_joint" pos="0 0 0" axis="0 0 1" range="-0.04545 1.56" actuatorfrcrange="-1 1" damping="0.0" armature="0.0" frictionloss="0.0" />
            <geom name="ring_intermediate_collision_part000" type="mesh" mesh="right_index_intermediate_collision000" group="1" rgba="0.9 0.35 0.1 0.65" />
            <geom name="ring_intermediate_collision_part001" type="mesh" mesh="right_index_intermediate_collision001" group="1" rgba="0.9 0.35 0.1 0.65" />
            <geom name="ring_intermediate_collision_part002" type="mesh" mesh="right_index_intermediate_collision002" group="1" rgba="0.9 0.35 0.1 0.65" />
            <body name="ring_tip" pos="-0.0008 0.045 -0.005" />
          </body>
        </body>
        <body name="pinky_proximal" pos="0.00028533 -0.13571 0.025488" quat="0.0523224 0.99863 0 0">
          <inertial pos="0.001297 0.011934 -0.0060001" quat="0.51013 0.489693 -0.510106 0.489653" mass="0.0042403" diaginertia="6.9397e-07 6.62865e-07 2.10915e-07" />
          <joint name="pinky_proximal_joint" pos="0 0 0" axis="0 0 1" range="0 1.47" actuatorfrcrange="-1 1" damping="0.1" armature="0.0002" frictionloss="0.0" />
          <geom name="pinky_proximal_collision_part000" type="mesh" mesh="right_index_proximal_collision000" group="1" rgba="0.9 0.35 0.1 0.65" />
          <geom name="pinky_proximal_collision_part001" type="mesh" mesh="right_index_proximal_collision001" group="1" rgba="0.9 0.35 0.1 0.65" />
          <body name="pinky_intermediate" pos="-0.0024229 0.032041 -0.001">
            <inertial pos="0.0024748 0.016203 -0.0050031" quat="0.47398 0.528862 -0.469291 0.524799" mass="0.0035996" diaginertia="4.4867e-07 4.43723e-07 6.56538e-08" />
            <joint name="pinky_intermediate_joint" pos="0 0 0" axis="0 0 1" range="-0.04545 1.56" actuatorfrcrange="-1 1" damping="0.0" armature="0.0" frictionloss="0.0" />
            <geom type="mesh" mesh="right_pinky_intermediate_collision000" group="1" rgba="0.9 0.35 0.1 0.65" />
            <body name="pinky_tip" pos="-0.0008 0.037 -0.005" />
          </body>
        </body>
      </body>
    </body>
  </worldbody>
  <contact>
    <exclude name="ex_hand_base_link_thumb_proximal_base" body1="hand_base_link" body2="thumb_proximal_base" />
    <exclude name="ex_hand_base_link_thumb_proximal" body1="hand_base_link" body2="thumb_proximal" />
    <exclude name="ex_thumb_proximal_base_thumb_proximal" body1="thumb_proximal_base" body2="thumb_proximal" />
    <exclude name="ex_thumb_proximal_thumb_intermediate" body1="thumb_proximal" body2="thumb_intermediate" />
    <exclude name="ex_thumb_intermediate_thumb_distal" body1="thumb_intermediate" body2="thumb_distal" />
    <exclude name="ex_thumb_distal_thumb_tip" body1="thumb_distal" body2="thumb_tip" />
    <exclude name="ex_hand_base_link_index_proximal" body1="hand_base_link" body2="index_proximal" />
    <exclude name="ex_index_proximal_index_intermediate" body1="index_proximal" body2="index_intermediate" />
    <exclude name="ex_index_intermediate_index_tip" body1="index_intermediate" body2="index_tip" />
    <exclude name="ex_hand_base_link_middle_proximal" body1="hand_base_link" body2="middle_proximal" />
    <exclude name="ex_middle_proximal_middle_intermediate" body1="middle_proximal" body2="middle_intermediate" />
    <exclude name="ex_middle_intermediate_middle_tip" body1="middle_intermediate" body2="middle_tip" />
    <exclude name="ex_hand_base_link_ring_proximal" body1="hand_base_link" body2="ring_proximal" />
    <exclude name="ex_ring_proximal_ring_intermediate" body1="ring_proximal" body2="ring_intermediate" />
    <exclude name="ex_ring_intermediate_ring_tip" body1="ring_intermediate" body2="ring_tip" />
    <exclude name="ex_hand_base_link_pinky_proximal" body1="hand_base_link" body2="pinky_proximal" />
    <exclude name="ex_pinky_proximal_pinky_intermediate" body1="pinky_proximal" body2="pinky_intermediate" />
    <exclude name="ex_pinky_intermediate_pinky_tip" body1="pinky_intermediate" body2="pinky_tip" />
  </contact>
  <equality>
    <joint name="thumb_intermediate_joint_mimic" joint1="thumb_intermediate_joint" joint2="thumb_proximal_pitch_joint" polycoef="0 1.334 0 0 0" />
    <joint name="thumb_distal_joint_mimic" joint1="thumb_distal_joint" joint2="thumb_proximal_pitch_joint" polycoef="0 0.667 0 0 0" />
    <joint name="index_intermediate_joint_mimic" joint1="index_intermediate_joint" joint2="index_proximal_joint" polycoef="-0.04545 1.06399 0 0 0" />
    <joint name="middle_intermediate_joint_mimic" joint1="middle_intermediate_joint" joint2="middle_proximal_joint" polycoef="-0.04545 1.06399 0 0 0" />
    <joint name="ring_intermediate_joint_mimic" joint1="ring_intermediate_joint" joint2="ring_proximal_joint" polycoef="-0.04545 1.06399 0 0 0" />
    <joint name="pinky_intermediate_joint_mimic" joint1="pinky_intermediate_joint" joint2="pinky_proximal_joint" polycoef="-0.04545 1.06399 0 0 0" />
  </equality>
  <actuator>
    <position name="thumb_proximal_yaw_joint_actuator" joint="thumb_proximal_yaw_joint" kp="1" ctrlrange="0.0 1.308" />
    <position name="thumb_proximal_pitch_joint_actuator" joint="thumb_proximal_pitch_joint" kp="1" ctrlrange="0 0.6" />
    <position name="index_proximal_joint_actuator" joint="index_proximal_joint" kp="1" ctrlrange="0 1.47" />
    <position name="middle_proximal_joint_actuator" joint="middle_proximal_joint" kp="1" ctrlrange="0 1.47" />
    <position name="ring_proximal_joint_actuator" joint="ring_proximal_joint" kp="1" ctrlrange="0 1.47" />
    <position name="pinky_proximal_joint_actuator" joint="pinky_proximal_joint" kp="1" ctrlrange="0 1.47" />
  </actuator>
</mujoco>