<mujoco model="liberhand_right">
  <compiler angle="radian" meshdir="/home/ccs/repositories/sq_dex_grasp/assets/hands/liberhand/"/>

  <option timestep="0.001" impratio="10" gravity="0 0 0" cone="elliptic" noslip_iterations="2"/>

  <visual>
    <global offwidth="3840" offheight="2160"/>
  </visual>

  <default>
    <default/>
  </default>

  <asset>
    <texture type="skybox" colorspace="auto" builtin="gradient" rgb1="1 1 1" rgb2="1 1 1" width="32" height="192"/>
    <texture type="2d" colorspace="linear" name="035_power_drill_texture" file="/home/ccs/repositories/sq_dex_grasp/assets/ycb_datasets/035_power_drill/texture_map.png"/>
    <material name="035_power_drill_material" texture="035_power_drill_texture"/>
    <mesh name="palm" file="meshes/palm.STL"/>
    <mesh name="f11" file="meshes/f11.STL"/>
    <mesh name="f12" file="meshes/f12.STL"/>
    <mesh name="f13" file="meshes/f13.STL"/>
    <mesh name="f14" file="meshes/f14.STL"/>
    <mesh name="f21" file="meshes/f21.STL"/>
    <mesh name="f22" file="meshes/f22.STL"/>
    <mesh name="f23" file="meshes/f23.STL"/>
    <mesh name="f24" file="meshes/f24.STL"/>
    <mesh name="f31" file="meshes/f31.STL"/>
    <mesh name="f32" file="meshes/f32.STL"/>
    <mesh name="f33" file="meshes/f33.STL"/>
    <mesh name="f34" file="meshes/f34.STL"/>
    <mesh name="f41" file="meshes/f41.STL"/>
    <mesh name="f42" file="meshes/f42.STL"/>
    <mesh name="f43" file="meshes/f43.STL"/>
    <mesh name="f44" file="meshes/f44.STL"/>
    <mesh name="f51" file="meshes/f51.STL"/>
    <mesh name="f52" file="meshes/f52.STL"/>
    <mesh name="f53" file="meshes/f53.STL"/>
    <mesh name="f54" file="meshes/f54.STL"/>
    <mesh name="035_power_drill_visual_mesh" file="/home/ccs/repositories/sq_dex_grasp/assets/ycb_datasets/035_power_drill/inertia.obj"/>
    <mesh name="035_power_drill_collision_mesh_0" file="/home/ccs/repositories/sq_dex_grasp/assets/ycb_datasets/035_power_drill/meshes/coacd_convex_piece_0.obj"/>
    <mesh name="035_power_drill_collision_mesh_1" file="/home/ccs/repositories/sq_dex_grasp/assets/ycb_datasets/035_power_drill/meshes/coacd_convex_piece_1.obj"/>
    <mesh name="035_power_drill_collision_mesh_2" file="/home/ccs/repositories/sq_dex_grasp/assets/ycb_datasets/035_power_drill/meshes/coacd_convex_piece_10.obj"/>
    <mesh name="035_power_drill_collision_mesh_3" file="/home/ccs/repositories/sq_dex_grasp/assets/ycb_datasets/035_power_drill/meshes/coacd_convex_piece_11.obj"/>
    <mesh name="035_power_drill_collision_mesh_4" file="/home/ccs/repositories/sq_dex_grasp/assets/ycb_datasets/035_power_drill/meshes/coacd_convex_piece_12.obj"/>
    <mesh name="035_power_drill_collision_mesh_5" file="/home/ccs/repositories/sq_dex_grasp/assets/ycb_datasets/035_power_drill/meshes/coacd_convex_piece_2.obj"/>
    <mesh name="035_power_drill_collision_mesh_6" file="/home/ccs/repositories/sq_dex_grasp/assets/ycb_datasets/035_power_drill/meshes/coacd_convex_piece_3.obj"/>
    <mesh name="035_power_drill_collision_mesh_7" file="/home/ccs/repositories/sq_dex_grasp/assets/ycb_datasets/035_power_drill/meshes/coacd_convex_piece_4.obj"/>
    <mesh name="035_power_drill_collision_mesh_8" file="/home/ccs/repositories/sq_dex_grasp/assets/ycb_datasets/035_power_drill/meshes/coacd_convex_piece_5.obj"/>
    <mesh name="035_power_drill_collision_mesh_9" file="/home/ccs/repositories/sq_dex_grasp/assets/ycb_datasets/035_power_drill/meshes/coacd_convex_piece_6.obj"/>
    <mesh name="035_power_drill_collision_mesh_10" file="/home/ccs/repositories/sq_dex_grasp/assets/ycb_datasets/035_power_drill/meshes/coacd_convex_piece_7.obj"/>
    <mesh name="035_power_drill_collision_mesh_11" file="/home/ccs/repositories/sq_dex_grasp/assets/ycb_datasets/035_power_drill/meshes/coacd_convex_piece_8.obj"/>
    <mesh name="035_power_drill_collision_mesh_12" file="/home/ccs/repositories/sq_dex_grasp/assets/ycb_datasets/035_power_drill/meshes/coacd_convex_piece_9.obj"/>
  </asset>

  <worldbody>
    <light pos="0 0 5" dir="0 0 -1" type="directional"/>
    <body name="hand_right_palm">
      <inertial pos="0 0 0" quat="0.994283 0.0215173 0.0263891 0.101206" mass="917780" diaginertia="1875.4 1570.2 644.013"/>
      <joint name="world_to_hand" type="free"/>
      <geom type="mesh" condim="4" friction="0.2 0.2" solref="0.003" solimp="0.4 0.99 0.0001" rgba="0.2 0.2 0.2 1" mesh="palm"/>
      <body name="hand_right_grasp" pos="0 0 -0.025" quat="0 0.382683 0 0.92388"/>
      <body name="hand_right_f11" pos="-0.022466 0.027654 0.043657" quat="0.5065 0.493412 0.506504 0.493412">
        <inertial pos="0 0.00069742 -0.0093798" quat="0.706804 0.0206991 -0.0206991 0.706804" mass="0.0033015" diaginertia="3.10586e-07 2e-07 1.39414e-07"/>
        <joint name="hand_right_f11_joint" pos="0 0 0" axis="0 0 -1" range="-0.4 0.4" actuatorfrcrange="-3000 3000" armature="0.0002" damping="0.1"/>
        <geom type="mesh" condim="4" friction="0.2 0.2" solref="0.003" solimp="0.4 0.99 0.0001" rgba="0.913725 0.913725 0.847059 1" mesh="f11"/>
        <body name="hand_right_f12" quat="0.499998 0.5 0.500002 0.5">
          <inertial pos="0.026032 -0.0074611 2.268e-05" quat="-0.330388 0.713877 -0.0698403 0.613471" mass="0.058465" diaginertia="1.66096e-05 1.57486e-05 2.27188e-06"/>
          <joint name="hand_right_f12_joint" pos="0 0 0" axis="0 0 1" range="0 1.9" actuatorfrcrange="-3000 3000" armature="0.0002" damping="0.1"/>
          <geom type="mesh" condim="4" friction="0.2 0.2" solref="0.003" solimp="0.4 0.99 0.0001" rgba="0.913725 0.913725 0.847059 1" mesh="f12"/>
          <body name="hand_right_f13" pos="0.048883 -0.018383 0">
            <inertial pos="0.0090975 -0.0015069 0.0013415" quat="0.368759 0.472545 0.444032 0.665998" mass="0.014574" diaginertia="2.15877e-06 1.8024e-06 8.18837e-07"/>
            <joint name="hand_right_f13_joint" pos="0 0 0" axis="0 0 1" range="0 1.65" actuatorfrcrange="-3000 3000" armature="0.0002" damping="0.1"/>
            <geom type="mesh" condim="4" friction="0.2 0.2" solref="0.003" solimp="0.4 0.99 0.0001" rgba="0.913725 0.913725 0.847059 1" mesh="f13"/>
            <body name="hand_right_f14" pos="0.0284 -0.0092477 0">
              <inertial pos="0.007749 -0.0041898 -0.00072552" quat="-0.376065 0.718367 -0.0331381 0.584317" mass="0.0055228" diaginertia="5.13712e-07 4.74117e-07 1.4217e-07"/>
              <joint name="hand_right_f14_joint" pos="0 0 0" axis="0 0 1" range="0 1.65" actuatorfrcrange="-3000 3000"/>
              <geom type="mesh" condim="4" friction="0.2 0.2" solref="0.003" solimp="0.4 0.99 0.0001" rgba="0.913725 0.913725 0.847059 1" mesh="f14"/>
              <body name="hand_right_f14_end" pos="0.019695 -0.0034802 0" quat="0.952334 0 0 -0.305059"/>
              <body name="hand_right_f1_eef" pos="0.02397 -0.01237 0" quat="0.825336 0 0 -0.564642"/>
            </body>
          </body>
        </body>
      </body>
      <body name="hand_right_f21" pos="-0.022466 0.0022583 0.053546" quat="0.499998 0.5 0.500002 0.5">
        <inertial pos="0 0.00069742 -0.0093798" quat="0.706804 0.0206991 -0.0206991 0.706804" mass="0.0033015" diaginertia="3.10586e-07 2e-07 1.39414e-07"/>
        <joint name="hand_right_f21_joint" pos="0 0 0" axis="0 0 -1" range="-0.4 0.4" actuatorfrcrange="-3000 3000" armature="0.0002" damping="0.1"/>
        <geom type="mesh" condim="4" friction="0.2 0.2" solref="0.003" solimp="0.4 0.99 0.0001" rgba="0.913725 0.913725 0.847059 1" mesh="f21"/>
        <body name="hand_right_f22" quat="0.499998 0.5 0.500002 0.5">
          <inertial pos="0.026032 -0.0074611 2.268e-05" quat="-0.330388 0.713877 -0.0698403 0.613471" mass="0.058465" diaginertia="1.66096e-05 1.57486e-05 2.27188e-06"/>
          <joint name="hand_right_f22_joint" pos="0 0 0" axis="0 0 1" range="0 1.9" actuatorfrcrange="-3000 3000" armature="0.0002" damping="0.1"/>
          <geom type="mesh" condim="4" friction="0.2 0.2" solref="0.003" solimp="0.4 0.99 0.0001" rgba="0.913725 0.913725 0.847059 1" mesh="f22"/>
          <body name="hand_right_f23" pos="0.048883 -0.018383 0">
            <inertial pos="0.0090975 -0.0015069 0.0013415" quat="0.368759 0.472545 0.444032 0.665998" mass="0.014574" diaginertia="2.15877e-06 1.8024e-06 8.18837e-07"/>
            <joint name="hand_right_f23_joint" pos="0 0 0" axis="0 0 1" range="0 1.65" actuatorfrcrange="-3000 3000" armature="0.0002" damping="0.1"/>
            <geom type="mesh" condim="4" friction="0.2 0.2" solref="0.003" solimp="0.4 0.99 0.0001" rgba="0.913725 0.913725 0.847059 1" mesh="f23"/>
            <body name="hand_right_f24" pos="0.0284 -0.0092477 0">
              <inertial pos="0.007749 -0.0041898 -0.00072552" quat="-0.376065 0.718367 -0.0331381 0.584317" mass="0.0055228" diaginertia="5.13712e-07 4.74117e-07 1.4217e-07"/>
              <joint name="hand_right_f24_joint" pos="0 0 0" axis="0 0 1" range="0 1.65" actuatorfrcrange="-3000 3000"/>
              <geom type="mesh" condim="4" friction="0.2 0.2" solref="0.003" solimp="0.4 0.99 0.0001" rgba="0.913725 0.913725 0.847059 1" mesh="f24"/>
              <body name="hand_right_f24_end" pos="0.019695 -0.0034802 0" quat="0.952334 0 0 -0.305059"/>
              <body name="hand_right_f2_eef" pos="0.02397 -0.01237 0" quat="0.825336 0 0 -0.564642"/>
            </body>
          </body>
        </body>
      </body>
      <body name="hand_right_f31" pos="-0.021466 -0.017542 0.047798" quat="0.499998 0.5 0.500002 0.5">
        <inertial pos="-6.964e-05 -0.00044078 -0.012759" quat="0.706754 0.0223246 -0.0223246 0.706754" mass="0.0085521" diaginertia="7.6253e-07 7.6e-07 1.2747e-07"/>
        <joint name="hand_right_f31_joint" pos="0 0 0" axis="0 0 -1" range="-0.4 0.4" actuatorfrcrange="-3000 3000" armature="0.0002" damping="0.1"/>
        <geom type="mesh" condim="4" friction="0.2 0.2" solref="0.003" solimp="0.4 0.99 0.0001" rgba="0.913725 0.913725 0.847059 1" mesh="f31"/>
        <body name="hand_right_f32" quat="0.499998 0.5 0.500002 0.5">
          <inertial pos="0.025132 0.0031733 -8.727e-05" quat="-0.0229244 0.706735 0.0229244 0.706735" mass="0.01244" diaginertia="2.41e-06 2.29779e-06 4.42207e-07"/>
          <joint name="hand_right_f32_joint" pos="0 0 0" axis="0 0 1" range="0 1.65" actuatorfrcrange="-3000 3000" armature="0.0002" damping="0.1"/>
          <geom type="mesh" condim="4" friction="0.2 0.2" solref="0.003" solimp="0.4 0.99 0.0001" rgba="0.913725 0.913725 0.847059 1" mesh="f32"/>
          <body name="hand_right_f33" pos="0.044995 0.00066781 0">
            <inertial pos="0.010032 -0.00058707 -9.093e-05" quat="0.451397 0.451397 0.54428 0.54428" mass="0.0071009" diaginertia="7.05057e-07 7e-07 2.64943e-07"/>
            <joint name="hand_right_f33_joint" pos="0 0 0" axis="0 0 1" range="0 1.65" actuatorfrcrange="-3000 3000"/>
            <geom type="mesh" condim="4" friction="0.2 0.2" solref="0.003" solimp="0.4 0.99 0.0001" rgba="0.913725 0.913725 0.847059 1" mesh="f33"/>
            <body name="hand_right_f34" pos="0.024601 -0.0044465 0">
              <inertial pos="0.010482 -0.0030354 -1.03e-05" quat="-0.0992525 0.700106 0.0992525 0.700106" mass="0.0049513" diaginertia="3.7e-07 3.37361e-07 1.12639e-07"/>
              <joint name="hand_right_f34_joint" pos="0 0 0" axis="0 0 1" range="0 1.65" actuatorfrcrange="-3000 3000"/>
              <geom type="mesh" condim="4" friction="0.2 0.2" solref="0.003" solimp="0.4 0.99 0.0001" rgba="0.913725 0.913725 0.847059 1" mesh="f34"/>
              <body name="hand_right_f34_end" pos="0.021134 0.0011803 0" quat="0.980067 0 0 -0.198669"/>
              <body name="hand_right_f3_eef" pos="0.02707 -0.00731 0" quat="0.825336 0 0 -0.564642"/>
            </body>
          </body>
        </body>
      </body>
      <body name="hand_right_f41" pos="-0.021466 -0.034458 0.032384" quat="0.491196 0.50865 0.491199 0.50865">
        <inertial pos="-6.964e-05 -0.00044078 -0.012759" quat="0.706754 0.0223246 -0.0223246 0.706754" mass="0.0085521" diaginertia="7.6253e-07 7.6e-07 1.2747e-07"/>
        <joint name="hand_right_f41_joint" pos="0 0 0" axis="0 0 -1" range="-0.4 0.4" actuatorfrcrange="-3000 3000" armature="0.0002" damping="0.1"/>
        <geom type="mesh" condim="4" friction="0.2 0.2" solref="0.003" solimp="0.4 0.99 0.0001" rgba="0.913725 0.913725 0.847059 1" mesh="f41"/>
        <body name="hand_right_f42" quat="0.499998 0.5 0.500002 0.5">
          <inertial pos="0.021044 0.0035949 -7.944e-05" quat="-0.011899 0.707007 0.011899 0.707007" mass="0.0096409" diaginertia="1.35e-06 1.24101e-06 3.4899e-07"/>
          <joint name="hand_right_f42_joint" pos="0 0 0" axis="0 0 1" range="0 1.6" actuatorfrcrange="-3000 3000" armature="0.0002" damping="0.1"/>
          <geom type="mesh" condim="4" friction="0.2 0.2" solref="0.003" solimp="0.4 0.99 0.0001" rgba="0.913725 0.913725 0.847059 1" mesh="f42"/>
          <body name="hand_right_f43" pos="0.035975 0.001338 0">
            <inertial pos="0.010032 -0.00058707 -9.093e-05" quat="0.451397 0.451397 0.54428 0.54428" mass="0.0071009" diaginertia="7.05057e-07 7e-07 2.64943e-07"/>
            <joint name="hand_right_f43_joint" pos="0 0 0" axis="0 0 1" range="0 1.65" actuatorfrcrange="-3000 3000"/>
            <geom type="mesh" condim="4" friction="0.2 0.2" solref="0.003" solimp="0.4 0.99 0.0001" rgba="0.913725 0.913725 0.847059 1" mesh="f43"/>
            <body name="hand_right_f44" pos="0.024621 -0.004339 0">
              <inertial pos="0.010482 -0.0030354 -1.03e-05" quat="-0.0992525 0.700106 0.0992525 0.700106" mass="0.0049513" diaginertia="3.7e-07 3.37361e-07 1.12639e-07"/>
              <joint name="hand_right_f44_joint" pos="0 0 0" axis="0 0 1" range="0 1.65" actuatorfrcrange="-3000 3000"/>
              <geom type="mesh" condim="4" friction="0.2 0.2" solref="0.003" solimp="0.4 0.99 0.0001" rgba="0.913725 0.913725 0.847059 1" mesh="f44"/>
              <body name="hand_right_f44_end" pos="0.021123 0.0013734 0" quat="0.985585 0 0 -0.169182"/>
              <body name="hand_right_f4_eef" pos="0.02707 -0.00731 0" quat="0.825336 0 0 -0.564642"/>
            </body>
          </body>
        </body>
      </body>
      <body name="hand_right_f51" pos="-0.00049657 0.0084524 -0.066754">
        <inertial pos="0.0053991 0.0016936 0.01157" quat="0.382167 0.6714 0.53871 0.336098" mass="0.022542" diaginertia="5.25338e-06 3.56442e-06 2.8022e-06"/>
        <joint name="hand_right_f51_joint" pos="0 0 0" axis="0 0 -1" range="0 1.9" actuatorfrcrange="-3000 3000" armature="0.0002" damping="0.1"/>
        <geom type="mesh" condim="4" friction="0.2 0.2" solref="0.003" solimp="0.4 0.99 0.0001" rgba="0.913725 0.913725 0.847059 1" mesh="f51"/>
        <body name="hand_right_f52" pos="0.0092399 0.0031582 0.022073" quat="0.31611 0.573949 0.549177 0.518712">
          <inertial pos="0.03317 -0.0064258 -0.00083733" quat="0.0733623 0.670395 0.154724 0.721975" mass="0.12909" diaginertia="6.93324e-05 6.44145e-05 1.53331e-05"/>
          <joint name="hand_right_f52_joint" pos="0 0 0" axis="0 0 1" range="0 0.8" actuatorfrcrange="-3000 3000" armature="0.0002" damping="0.1"/>
          <geom type="mesh" condim="4" friction="0.2 0.2" solref="0.003" solimp="0.4 0.99 0.0001" rgba="0.913725 0.913725 0.847059 1" mesh="f52"/>
          <body name="hand_right_f53" pos="0.0654 0 0">
            <inertial pos="0.021453 0.0041043 -5.93e-06" quat="0.499752 0.496324 0.499565 0.504327" mass="0.011849" diaginertia="1.94008e-06 1.88008e-06 6.5984e-07"/>
            <joint name="hand_right_f53_joint" pos="0 0 0" axis="0 0 1" range="0 1.65" actuatorfrcrange="-3000 3000" armature="0.0002" damping="0.1"/>
            <geom type="mesh" condim="4" friction="0.2 0.2" solref="0.003" solimp="0.4 0.99 0.0001" rgba="0.913725 0.913725 0.847059 1" mesh="f53"/>
            <body name="hand_right_f54" pos="0.035837 0.0034221 0">
              <inertial pos="0.013824 -0.0017677 -5.567e-05" quat="0.453204 0.453204 0.542776 0.542776" mass="0.010348" diaginertia="1.3772e-06 1.17e-06 5.228e-07"/>
              <joint name="hand_right_f54_joint" pos="0 0 0" axis="0 0 1" range="0 1.65" actuatorfrcrange="-3000 3000"/>
              <geom type="mesh" condim="4" friction="0.2 0.2" solref="0.003" solimp="0.4 0.99 0.0001" rgba="0.913725 0.913725 0.847059 1" mesh="f54"/>
              <body name="hand_right_f54_end" pos="0.024 0.0044004 0" quat="0.998201 0 0 -0.059964"/>
              <body name="hand_right_f5_eef" pos="0.03483 -0.0034 0" quat="0.921061 0 0 -0.389418"/>
            </body>
          </body>
        </body>
      </body>
    </body>
    <body name="035_power_drill">
      <inertial pos="0 0 0" mass="0.895" diaginertia="0.00139263 0.0036306 0.00478517"/>
      <geom name="035_power_drill_visual_geom" type="mesh" contype="0" conaffinity="0" condim="4" friction="0.2 0.2" solref="0.003" solimp="0.4 0.99 0.0001" material="035_power_drill_material" mesh="035_power_drill_visual_mesh"/>
      <geom name="035_power_drill_collision_geom_0" type="mesh" condim="4" group="3" friction="0.2 0.2" solref="0.003" solimp="0.4 0.99 0.0001" mesh="035_power_drill_collision_mesh_0"/>
      <geom name="035_power_drill_collision_geom_1" type="mesh" condim="4" group="3" friction="0.2 0.2" solref="0.003" solimp="0.4 0.99 0.0001" mesh="035_power_drill_collision_mesh_1"/>
      <geom name="035_power_drill_collision_geom_2" type="mesh" condim="4" group="3" friction="0.2 0.2" solref="0.003" solimp="0.4 0.99 0.0001" mesh="035_power_drill_collision_mesh_2"/>
      <geom name="035_power_drill_collision_geom_3" type="mesh" condim="4" group="3" friction="0.2 0.2" solref="0.003" solimp="0.4 0.99 0.0001" mesh="035_power_drill_collision_mesh_3"/>
      <geom name="035_power_drill_collision_geom_4" type="mesh" condim="4" group="3" friction="0.2 0.2" solref="0.003" solimp="0.4 0.99 0.0001" mesh="035_power_drill_collision_mesh_4"/>
      <geom name="035_power_drill_collision_geom_5" type="mesh" condim="4" group="3" friction="0.2 0.2" solref="0.003" solimp="0.4 0.99 0.0001" mesh="035_power_drill_collision_mesh_5"/>
      <geom name="035_power_drill_collision_geom_6" type="mesh" condim="4" group="3" friction="0.2 0.2" solref="0.003" solimp="0.4 0.99 0.0001" mesh="035_power_drill_collision_mesh_6"/>
      <geom name="035_power_drill_collision_geom_7" type="mesh" condim="4" group="3" friction="0.2 0.2" solref="0.003" solimp="0.4 0.99 0.0001" mesh="035_power_drill_collision_mesh_7"/>
      <geom name="035_power_drill_collision_geom_8" type="mesh" condim="4" group="3" friction="0.2 0.2" solref="0.003" solimp="0.4 0.99 0.0001" mesh="035_power_drill_collision_mesh_8"/>
      <geom name="035_power_drill_collision_geom_9" type="mesh" condim="4" group="3" friction="0.2 0.2" solref="0.003" solimp="0.4 0.99 0.0001" mesh="035_power_drill_collision_mesh_9"/>
      <geom name="035_power_drill_collision_geom_10" type="mesh" condim="4" group="3" friction="0.2 0.2" solref="0.003" solimp="0.4 0.99 0.0001" mesh="035_power_drill_collision_mesh_10"/>
      <geom name="035_power_drill_collision_geom_11" type="mesh" condim="4" group="3" friction="0.2 0.2" solref="0.003" solimp="0.4 0.99 0.0001" mesh="035_power_drill_collision_mesh_11"/>
      <geom name="035_power_drill_collision_geom_12" type="mesh" condim="4" group="3" friction="0.2 0.2" solref="0.003" solimp="0.4 0.99 0.0001" mesh="035_power_drill_collision_mesh_12"/>
    </body>
  </worldbody>

  <contact>
    <exclude name="ex_r_palm_f11" body1="hand_right_palm" body2="hand_right_f11"/>
    <exclude name="ex_r_palm_f12" body1="hand_right_palm" body2="hand_right_f12"/>
    <exclude name="ex_r_palm_f21" body1="hand_right_palm" body2="hand_right_f21"/>
    <exclude name="ex_r_palm_f22" body1="hand_right_palm" body2="hand_right_f22"/>
    <exclude name="ex_r_palm_f31" body1="hand_right_palm" body2="hand_right_f31"/>
    <exclude name="ex_r_palm_f32" body1="hand_right_palm" body2="hand_right_f32"/>
    <exclude name="ex_r_palm_f41" body1="hand_right_palm" body2="hand_right_f41"/>
    <exclude name="ex_r_palm_f42" body1="hand_right_palm" body2="hand_right_f42"/>
    <exclude name="ex_r_palm_f51" body1="hand_right_palm" body2="hand_right_f51"/>
    <exclude name="ex_r_palm_f52" body1="hand_right_palm" body2="hand_right_f52"/>
    <exclude name="ex_r_f11_f12" body1="hand_right_f11" body2="hand_right_f12"/>
    <exclude name="ex_r_f12_f13" body1="hand_right_f12" body2="hand_right_f13"/>
    <exclude name="ex_r_f13_f14" body1="hand_right_f13" body2="hand_right_f14"/>
    <exclude name="ex_r_f21_f22" body1="hand_right_f21" body2="hand_right_f22"/>
    <exclude name="ex_r_f22_f23" body1="hand_right_f22" body2="hand_right_f23"/>
    <exclude name="ex_r_f23_f24" body1="hand_right_f23" body2="hand_right_f24"/>
    <exclude name="ex_r_f31_f32" body1="hand_right_f31" body2="hand_right_f32"/>
    <exclude name="ex_r_f32_f33" body1="hand_right_f32" body2="hand_right_f33"/>
    <exclude name="ex_r_f33_f34" body1="hand_right_f33" body2="hand_right_f34"/>
    <exclude name="ex_r_f41_f42" body1="hand_right_f41" body2="hand_right_f42"/>
    <exclude name="ex_r_f42_f43" body1="hand_right_f42" body2="hand_right_f43"/>
    <exclude name="ex_r_f43_f44" body1="hand_right_f43" body2="hand_right_f44"/>
    <exclude name="ex_r_f51_f52" body1="hand_right_f51" body2="hand_right_f52"/>
    <exclude name="ex_r_f52_f53" body1="hand_right_f52" body2="hand_right_f53"/>
    <exclude name="ex_r_f53_f54" body1="hand_right_f53" body2="hand_right_f54"/>
  </contact>

  <equality>
    <joint joint1="hand_right_f14_joint" joint2="hand_right_f13_joint" polycoef="0.009423 2.05176 -1.31331 0.650234 -0.139774" solref="0.002" solimp="0.9 0.99"/>
    <joint joint1="hand_right_f24_joint" joint2="hand_right_f23_joint" polycoef="0.009423 2.05176 -1.31331 0.650234 -0.139774" solref="0.002" solimp="0.9 0.99"/>
    <joint joint1="hand_right_f33_joint" joint2="hand_right_f32_joint" polycoef="0.001338 1.41247 -0.421321 0.146794 -0.022447" solref="0.002" solimp="0.9 0.99"/>
    <joint joint1="hand_right_f34_joint" joint2="hand_right_f33_joint" polycoef="-0.000471 1.10291 -0.263366 0.025065 -0.007574" solref="0.002" solimp="0.9 0.99"/>
    <joint joint1="hand_right_f43_joint" joint2="hand_right_f42_joint" polycoef="0.001871 1.35367 -0.361404 0.068408 0.012166" solref="0.002" solimp="0.9 0.99"/>
    <joint joint1="hand_right_f44_joint" joint2="hand_right_f43_joint" polycoef="-0.000471 1.10291 -0.263366 0.025065 -0.007574" solref="0.002" solimp="0.9 0.99"/>
    <joint joint1="hand_right_f54_joint" joint2="hand_right_f53_joint" polycoef="0.001018 1.61879 -0.733579 0.366074 -0.086615" solref="0.002" solimp="0.9 0.99"/>
  </equality>

  <actuator>
    <general name="M_hand_right_f11_joint" joint="hand_right_f11_joint" ctrlrange="-0.4 0.4" forcerange="-3000 3000" biastype="affine" gainprm="10" biasprm="0 -10"/>
    <general name="M_hand_right_f12_joint" joint="hand_right_f12_joint" ctrlrange="0 1.9" forcerange="-3000 3000" biastype="affine" gainprm="10" biasprm="0 -10"/>
    <general name="M_hand_right_f13_joint" joint="hand_right_f13_joint" ctrlrange="0 1.65" forcerange="-3000 3000" biastype="affine" gainprm="10" biasprm="0 -10"/>
    <general name="M_hand_right_f21_joint" joint="hand_right_f21_joint" ctrlrange="-0.4 0.4" forcerange="-3000 3000" biastype="affine" gainprm="10" biasprm="0 -10"/>
    <general name="M_hand_right_f22_joint" joint="hand_right_f22_joint" ctrlrange="0 1.9" forcerange="-3000 3000" biastype="affine" gainprm="10" biasprm="0 -10"/>
    <general name="M_hand_right_f23_joint" joint="hand_right_f23_joint" ctrlrange="0 1.65" forcerange="-3000 3000" biastype="affine" gainprm="10" biasprm="0 -10"/>
    <general name="M_hand_right_f31_joint" joint="hand_right_f31_joint" ctrlrange="-0.4 0" forcerange="-3000 3000" biastype="affine" gainprm="10" biasprm="0 -10"/>
    <general name="M_hand_right_f32_joint" joint="hand_right_f32_joint" ctrlrange="0 1.65" forcerange="-3000 3000" biastype="affine" gainprm="10" biasprm="0 -10"/>
    <general name="M_hand_right_f41_joint" joint="hand_right_f41_joint" ctrlrange="-0.4 0" forcerange="-3000 3000" biastype="affine" gainprm="10" biasprm="0 -10"/>
    <general name="M_hand_right_f42_joint" joint="hand_right_f42_joint" ctrlrange="0 1.6" forcerange="-3000 3000" biastype="affine" gainprm="10" biasprm="0 -10"/>
    <general name="M_hand_right_f51_joint" joint="hand_right_f51_joint" ctrlrange="0 1.9" forcerange="-3000 3000" biastype="affine" gainprm="10" biasprm="0 -10"/>
    <general name="M_hand_right_f52_joint" joint="hand_right_f52_joint" ctrlrange="0 0.8" forcerange="-3000 3000" biastype="affine" gainprm="10" biasprm="0 -10"/>
    <general name="M_hand_right_f53_joint" joint="hand_right_f53_joint" ctrlrange="0 1.65" forcerange="-3000 3000" biastype="affine" gainprm="10" biasprm="0 -10"/>
  </actuator>
</mujoco>
